{"cells":[{"cell_type":"code","execution_count":10,"metadata":{"colab":{"base_uri":"https://localhost:8080/"},"executionInfo":{"elapsed":5928,"status":"ok","timestamp":1683532595462,"user":{"displayName":"갱단","userId":"00887275859011159220"},"user_tz":-540},"id":"iOgg8Ek0Y1r5","outputId":"c46efbe0-b77d-40ae-b4b7-78950e04edd2"},"outputs":[{"name":"stdout","output_type":"stream","text":["Mounted at /gdrive\n"]}],"source":["from google.colab import drive \n","drive.mount('/gdrive')"]},{"cell_type":"code","execution_count":null,"metadata":{"colab":{"background_save":true,"base_uri":"https://localhost:8080/"},"id":"ZhXbELBpY3CW"},"outputs":[{"name":"stderr","output_type":"stream","text":["ERROR:root:Internal Python error in the inspect module.\n","Below is the traceback from this internal error.\n","\n","ERROR:root:Internal Python error in the inspect module.\n","Below is the traceback from this internal error.\n","\n","ERROR:root:Internal Python error in the inspect module.\n","Below is the traceback from this internal error.\n","\n"]},{"name":"stdout","output_type":"stream","text":["Traceback (most recent call last):\n","  File \"/usr/local/lib/python3.10/dist-packages/IPython/core/interactiveshell.py\", line 3553, in run_code\n","    exec(code_obj, self.user_global_ns, self.user_ns)\n","  File \"\u003cipython-input-16-5f7c27aa4b2b\u003e\", line 2, in \u003ccell line: 2\u003e\n","    get_ipython().run_line_magic('cd', '/gdrive/My Drive/PHODO/Segmentation Model/Yolo_custom/yolov5')\n","  File \"/usr/local/lib/python3.10/dist-packages/IPython/core/interactiveshell.py\", line 2418, in run_line_magic\n","    result = fn(*args, **kwargs)\n","  File \"\u003cdecorator-gen-85\u003e\", line 2, in cd\n","  File \"/usr/local/lib/python3.10/dist-packages/IPython/core/magic.py\", line 187, in \u003clambda\u003e\n","    call = lambda f, *a, **k: f(*a, **k)\n","  File \"/usr/local/lib/python3.10/dist-packages/IPython/core/magics/osm.py\", line 342, in cd\n","    oldcwd = os.getcwd()\n","OSError: [Errno 107] Transport endpoint is not connected\n","\n","During handling of the above exception, another exception occurred:\n","\n","Traceback (most recent call last):\n","  File \"/usr/local/lib/python3.10/dist-packages/IPython/core/interactiveshell.py\", line 2099, in showtraceback\n","    stb = value._render_traceback_()\n","AttributeError: 'OSError' object has no attribute '_render_traceback_'\n","\n","During handling of the above exception, another exception occurred:\n","\n","Traceback (most recent call last):\n","  File \"/usr/local/lib/python3.10/dist-packages/IPython/core/ultratb.py\", line 1101, in get_records\n","    return _fixed_getinnerframes(etb, number_of_lines_of_context, tb_offset)\n","  File \"/usr/local/lib/python3.10/dist-packages/IPython/core/ultratb.py\", line 248, in wrapped\n","    return f(*args, **kwargs)\n","  File \"/usr/local/lib/python3.10/dist-packages/IPython/core/ultratb.py\", line 281, in _fixed_getinnerframes\n","    records = fix_frame_records_filenames(inspect.getinnerframes(etb, context))\n","  File \"/usr/lib/python3.10/inspect.py\", line 1662, in getinnerframes\n","    frameinfo = (tb.tb_frame,) + getframeinfo(tb, context)\n","  File \"/usr/lib/python3.10/inspect.py\", line 1620, in getframeinfo\n","    filename = getsourcefile(frame) or getfile(frame)\n","  File \"/usr/lib/python3.10/inspect.py\", line 829, in getsourcefile\n","    module = getmodule(object, filename)\n","  File \"/usr/lib/python3.10/inspect.py\", line 861, in getmodule\n","    file = getabsfile(object, _filename)\n","  File \"/usr/lib/python3.10/inspect.py\", line 845, in getabsfile\n","    return os.path.normcase(os.path.abspath(_filename))\n","  File \"/usr/lib/python3.10/posixpath.py\", line 384, in abspath\n","    cwd = os.getcwd()\n","OSError: [Errno 107] Transport endpoint is not connected\n","Traceback (most recent call last):\n","  File \"/usr/local/lib/python3.10/dist-packages/IPython/core/interactiveshell.py\", line 3553, in run_code\n","    exec(code_obj, self.user_global_ns, self.user_ns)\n","  File \"\u003cipython-input-16-5f7c27aa4b2b\u003e\", line 2, in \u003ccell line: 2\u003e\n","    get_ipython().run_line_magic('cd', '/gdrive/My Drive/PHODO/Segmentation Model/Yolo_custom/yolov5')\n","  File \"/usr/local/lib/python3.10/dist-packages/IPython/core/interactiveshell.py\", line 2418, in run_line_magic\n","    result = fn(*args, **kwargs)\n","  File \"\u003cdecorator-gen-85\u003e\", line 2, in cd\n","  File \"/usr/local/lib/python3.10/dist-packages/IPython/core/magic.py\", line 187, in \u003clambda\u003e\n","    call = lambda f, *a, **k: f(*a, **k)\n","  File \"/usr/local/lib/python3.10/dist-packages/IPython/core/magics/osm.py\", line 342, in cd\n","    oldcwd = os.getcwd()\n","OSError: [Errno 107] Transport endpoint is not connected\n","\n","During handling of the above exception, another exception occurred:\n","\n","Traceback (most recent call last):\n","  File \"/usr/local/lib/python3.10/dist-packages/IPython/core/interactiveshell.py\", line 2099, in showtraceback\n","    stb = value._render_traceback_()\n","AttributeError: 'OSError' object has no attribute '_render_traceback_'\n","\n","During handling of the above exception, another exception occurred:\n","\n","Traceback (most recent call last):\n","  File \"/usr/local/lib/python3.10/dist-packages/IPython/core/interactiveshell.py\", line 3473, in run_ast_nodes\n","    if (await self.run_code(code, result,  async_=asy)):\n","  File \"/usr/local/lib/python3.10/dist-packages/IPython/core/interactiveshell.py\", line 3575, in run_code\n","    self.showtraceback(running_compiled_code=True)\n","  File \"/usr/local/lib/python3.10/dist-packages/IPython/core/interactiveshell.py\", line 2101, in showtraceback\n","    stb = self.InteractiveTB.structured_traceback(etype,\n","  File \"/usr/local/lib/python3.10/dist-packages/IPython/core/ultratb.py\", line 1367, in structured_traceback\n","    return FormattedTB.structured_traceback(\n","  File \"/usr/local/lib/python3.10/dist-packages/IPython/core/ultratb.py\", line 1267, in structured_traceback\n","    return VerboseTB.structured_traceback(\n","  File \"/usr/local/lib/python3.10/dist-packages/IPython/core/ultratb.py\", line 1124, in structured_traceback\n","    formatted_exception = self.format_exception_as_a_whole(etype, evalue, etb, number_of_lines_of_context,\n","  File \"/usr/local/lib/python3.10/dist-packages/IPython/core/ultratb.py\", line 1082, in format_exception_as_a_whole\n","    last_unique, recursion_repeat = find_recursion(orig_etype, evalue, records)\n","  File \"/usr/local/lib/python3.10/dist-packages/IPython/core/ultratb.py\", line 382, in find_recursion\n","    return len(records), 0\n","TypeError: object of type 'NoneType' has no len()\n","\n","During handling of the above exception, another exception occurred:\n","\n","Traceback (most recent call last):\n","  File \"/usr/local/lib/python3.10/dist-packages/IPython/core/interactiveshell.py\", line 2099, in showtraceback\n","    stb = value._render_traceback_()\n","AttributeError: 'TypeError' object has no attribute '_render_traceback_'\n","\n","During handling of the above exception, another exception occurred:\n","\n","Traceback (most recent call last):\n","  File \"/usr/local/lib/python3.10/dist-packages/IPython/core/ultratb.py\", line 1101, in get_records\n","    return _fixed_getinnerframes(etb, number_of_lines_of_context, tb_offset)\n","  File \"/usr/local/lib/python3.10/dist-packages/IPython/core/ultratb.py\", line 248, in wrapped\n","    return f(*args, **kwargs)\n","  File \"/usr/local/lib/python3.10/dist-packages/IPython/core/ultratb.py\", line 281, in _fixed_getinnerframes\n","    records = fix_frame_records_filenames(inspect.getinnerframes(etb, context))\n","  File \"/usr/lib/python3.10/inspect.py\", line 1662, in getinnerframes\n","    frameinfo = (tb.tb_frame,) + getframeinfo(tb, context)\n","  File \"/usr/lib/python3.10/inspect.py\", line 1620, in getframeinfo\n","    filename = getsourcefile(frame) or getfile(frame)\n","  File \"/usr/lib/python3.10/inspect.py\", line 829, in getsourcefile\n","    module = getmodule(object, filename)\n","  File \"/usr/lib/python3.10/inspect.py\", line 861, in getmodule\n","    file = getabsfile(object, _filename)\n","  File \"/usr/lib/python3.10/inspect.py\", line 845, in getabsfile\n","    return os.path.normcase(os.path.abspath(_filename))\n","  File \"/usr/lib/python3.10/posixpath.py\", line 384, in abspath\n","    cwd = os.getcwd()\n","OSError: [Errno 107] Transport endpoint is not connected\n","Traceback (most recent call last):\n","  File \"/usr/local/lib/python3.10/dist-packages/IPython/core/interactiveshell.py\", line 3553, in run_code\n","    exec(code_obj, self.user_global_ns, self.user_ns)\n","  File \"\u003cipython-input-16-5f7c27aa4b2b\u003e\", line 2, in \u003ccell line: 2\u003e\n","    get_ipython().run_line_magic('cd', '/gdrive/My Drive/PHODO/Segmentation Model/Yolo_custom/yolov5')\n","  File \"/usr/local/lib/python3.10/dist-packages/IPython/core/interactiveshell.py\", line 2418, in run_line_magic\n","    result = fn(*args, **kwargs)\n","  File \"\u003cdecorator-gen-85\u003e\", line 2, in cd\n","  File \"/usr/local/lib/python3.10/dist-packages/IPython/core/magic.py\", line 187, in \u003clambda\u003e\n","    call = lambda f, *a, **k: f(*a, **k)\n","  File \"/usr/local/lib/python3.10/dist-packages/IPython/core/magics/osm.py\", line 342, in cd\n","    oldcwd = os.getcwd()\n","OSError: [Errno 107] Transport endpoint is not connected\n","\n","During handling of the above exception, another exception occurred:\n","\n","Traceback (most recent call last):\n","  File \"/usr/local/lib/python3.10/dist-packages/IPython/core/interactiveshell.py\", line 2099, in showtraceback\n","    stb = value._render_traceback_()\n","AttributeError: 'OSError' object has no attribute '_render_traceback_'\n","\n","During handling of the above exception, another exception occurred:\n","\n","Traceback (most recent call last):\n","  File \"/usr/local/lib/python3.10/dist-packages/IPython/core/interactiveshell.py\", line 3473, in run_ast_nodes\n","    if (await self.run_code(code, result,  async_=asy)):\n","  File \"/usr/local/lib/python3.10/dist-packages/IPython/core/interactiveshell.py\", line 3575, in run_code\n","    self.showtraceback(running_compiled_code=True)\n","  File \"/usr/local/lib/python3.10/dist-packages/IPython/core/interactiveshell.py\", line 2101, in showtraceback\n","    stb = self.InteractiveTB.structured_traceback(etype,\n","  File \"/usr/local/lib/python3.10/dist-packages/IPython/core/ultratb.py\", line 1367, in structured_traceback\n","    return FormattedTB.structured_traceback(\n","  File \"/usr/local/lib/python3.10/dist-packages/IPython/core/ultratb.py\", line 1267, in structured_traceback\n","    return VerboseTB.structured_traceback(\n","  File \"/usr/local/lib/python3.10/dist-packages/IPython/core/ultratb.py\", line 1124, in structured_traceback\n","    formatted_exception = self.format_exception_as_a_whole(etype, evalue, etb, number_of_lines_of_context,\n","  File \"/usr/local/lib/python3.10/dist-packages/IPython/core/ultratb.py\", line 1082, in format_exception_as_a_whole\n","    last_unique, recursion_repeat = find_recursion(orig_etype, evalue, records)\n","  File \"/usr/local/lib/python3.10/dist-packages/IPython/core/ultratb.py\", line 382, in find_recursion\n","    return len(records), 0\n","TypeError: object of type 'NoneType' has no len()\n","\n","During handling of the above exception, another exception occurred:\n","\n","Traceback (most recent call last):\n","  File \"/usr/local/lib/python3.10/dist-packages/IPython/core/interactiveshell.py\", line 2099, in showtraceback\n","    stb = value._render_traceback_()\n","AttributeError: 'TypeError' object has no attribute '_render_traceback_'\n","\n","During handling of the above exception, another exception occurred:\n","\n","Traceback (most recent call last):\n","  File \"/usr/local/lib/python3.10/dist-packages/IPython/core/interactiveshell.py\", line 3030, in _run_cell\n","    return runner(coro)\n","  File \"/usr/local/lib/python3.10/dist-packages/IPython/core/async_helpers.py\", line 78, in _pseudo_sync_runner\n","    coro.send(None)\n","  File \"/usr/local/lib/python3.10/dist-packages/IPython/core/interactiveshell.py\", line 3257, in run_cell_async\n","    has_raised = await self.run_ast_nodes(code_ast.body, cell_name,\n","  File \"/usr/local/lib/python3.10/dist-packages/IPython/core/interactiveshell.py\", line 3492, in run_ast_nodes\n","    self.showtraceback()\n","  File \"/usr/local/lib/python3.10/dist-packages/IPython/core/interactiveshell.py\", line 2101, in showtraceback\n","    stb = self.InteractiveTB.structured_traceback(etype,\n","  File \"/usr/local/lib/python3.10/dist-packages/IPython/core/ultratb.py\", line 1367, in structured_traceback\n","    return FormattedTB.structured_traceback(\n","  File \"/usr/local/lib/python3.10/dist-packages/IPython/core/ultratb.py\", line 1267, in structured_traceback\n","    return VerboseTB.structured_traceback(\n","  File \"/usr/local/lib/python3.10/dist-packages/IPython/core/ultratb.py\", line 1142, in structured_traceback\n","    formatted_exceptions += self.format_exception_as_a_whole(etype, evalue, etb, lines_of_context,\n","  File \"/usr/local/lib/python3.10/dist-packages/IPython/core/ultratb.py\", line 1082, in format_exception_as_a_whole\n","    last_unique, recursion_repeat = find_recursion(orig_etype, evalue, records)\n","  File \"/usr/local/lib/python3.10/dist-packages/IPython/core/ultratb.py\", line 382, in find_recursion\n","    return len(records), 0\n","TypeError: object of type 'NoneType' has no len()\n","\n","During handling of the above exception, another exception occurred:\n","\n","Traceback (most recent call last):\n","  File \"/usr/local/lib/python3.10/dist-packages/IPython/core/interactiveshell.py\", line 2099, in showtraceback\n","    stb = value._render_traceback_()\n","AttributeError: 'TypeError' object has no attribute '_render_traceback_'\n","\n","During handling of the above exception, another exception occurred:\n","\n","Traceback (most recent call last):\n","  File \"/usr/local/lib/python3.10/dist-packages/IPython/core/ultratb.py\", line 1101, in get_records\n","    return _fixed_getinnerframes(etb, number_of_lines_of_context, tb_offset)\n","  File \"/usr/local/lib/python3.10/dist-packages/IPython/core/ultratb.py\", line 248, in wrapped\n","    return f(*args, **kwargs)\n","  File \"/usr/local/lib/python3.10/dist-packages/IPython/core/ultratb.py\", line 281, in _fixed_getinnerframes\n","    records = fix_frame_records_filenames(inspect.getinnerframes(etb, context))\n","  File \"/usr/lib/python3.10/inspect.py\", line 1662, in getinnerframes\n","    frameinfo = (tb.tb_frame,) + getframeinfo(tb, context)\n","  File \"/usr/lib/python3.10/inspect.py\", line 1620, in getframeinfo\n","    filename = getsourcefile(frame) or getfile(frame)\n","  File \"/usr/lib/python3.10/inspect.py\", line 829, in getsourcefile\n","    module = getmodule(object, filename)\n","  File \"/usr/lib/python3.10/inspect.py\", line 861, in getmodule\n","    file = getabsfile(object, _filename)\n","  File \"/usr/lib/python3.10/inspect.py\", line 845, in getabsfile\n","    return os.path.normcase(os.path.abspath(_filename))\n","  File \"/usr/lib/python3.10/posixpath.py\", line 384, in abspath\n","    cwd = os.getcwd()\n","OSError: [Errno 107] Transport endpoint is not connected\n"]}],"source":["import os\n","%cd /gdrive/My Drive/PHODO/Segmentation Model/Yolo_custom/yolov5\n","!pwd"]},{"cell_type":"code","execution_count":null,"metadata":{"colab":{"base_uri":"https://localhost:8080/"},"executionInfo":{"elapsed":8639,"status":"ok","timestamp":1682789668850,"user":{"displayName":"갱단","userId":"00887275859011159220"},"user_tz":-540},"id":"_lOCtFXKFGbF","outputId":"90a6a0d7-056e-4d1f-f478-6bcc5f9c31ab"},"outputs":[{"name":"stdout","output_type":"stream","text":["Looking in indexes: https://pypi.org/simple, https://us-python.pkg.dev/colab-wheels/public/simple/\n","Collecting jdata\n","  Downloading jdata-0.5.3-py2.py3-none-any.whl (14 kB)\n","Requirement already satisfied: numpy\u003e=1.8.0 in /usr/local/lib/python3.10/dist-packages (from jdata) (1.22.4)\n","Installing collected packages: jdata\n","Successfully installed jdata-0.5.3\n"]}],"source":["!pip install jdata"]},{"cell_type":"code","execution_count":null,"metadata":{"id":"BNTUSBEuZAEU"},"outputs":[],"source":["import os\n","\n","!git clone https://github.com/ultralytics/yolov5.git # clone"]},{"cell_type":"code","execution_count":null,"metadata":{"id":"_SO6XOLgZKDG"},"outputs":[],"source":["%cd /gdrive/My Drive/PHODO/Segmentation Model/Yolo/yolov5\n","%pip install -r requirements.txt # install"]},{"cell_type":"code","execution_count":4,"metadata":{"colab":{"background_save":true,"base_uri":"https://localhost:8080/"},"executionInfo":{"elapsed":6636,"status":"ok","timestamp":1683530254701,"user":{"displayName":"갱단","userId":"00887275859011159220"},"user_tz":-540},"id":"sj7WNbPYcxF5"},"outputs":[{"name":"stderr","output_type":"stream","text":["ERROR:root:Internal Python error in the inspect module.\n","Below is the traceback from this internal error.\n","\n"]},{"name":"stdout","output_type":"stream","text":["Checking setup...\n"]},{"name":"stderr","output_type":"stream","text":["ERROR:root:Internal Python error in the inspect module.\n","Below is the traceback from this internal error.\n","\n","ERROR:root:Internal Python error in the inspect module.\n","Below is the traceback from this internal error.\n","\n"]},{"name":"stdout","output_type":"stream","text":["Traceback (most recent call last):\n","  File \"/usr/local/lib/python3.10/dist-packages/IPython/core/interactiveshell.py\", line 3553, in run_code\n","    exec(code_obj, self.user_global_ns, self.user_ns)\n","  File \"\u003cipython-input-16-72b12b7ac5f1\u003e\", line 3, in \u003ccell line: 3\u003e\n","    display = utils.notebook_init()  # checks\n","  File \"/gdrive/MyDrive/PHODO/Segmentation Model/Yolo_custom/yolov5/utils/__init__.py\", line 60, in notebook_init\n","    check_font()\n","  File \"/gdrive/MyDrive/PHODO/Segmentation Model/Yolo_custom/yolov5/utils/general.py\", line 500, in check_font\n","    if not font.exists() and not file.exists():\n","  File \"/usr/lib/python3.10/pathlib.py\", line 1290, in exists\n","    self.stat()\n","  File \"/usr/lib/python3.10/pathlib.py\", line 1097, in stat\n","    return self._accessor.stat(self, follow_symlinks=follow_symlinks)\n","OSError: [Errno 107] Transport endpoint is not connected: 'Arial.ttf'\n","\n","During handling of the above exception, another exception occurred:\n","\n","Traceback (most recent call last):\n","  File \"/usr/local/lib/python3.10/dist-packages/IPython/core/interactiveshell.py\", line 2099, in showtraceback\n","    stb = value._render_traceback_()\n","AttributeError: 'OSError' object has no attribute '_render_traceback_'\n","\n","During handling of the above exception, another exception occurred:\n","\n","Traceback (most recent call last):\n","  File \"/usr/local/lib/python3.10/dist-packages/IPython/core/ultratb.py\", line 1101, in get_records\n","    return _fixed_getinnerframes(etb, number_of_lines_of_context, tb_offset)\n","  File \"/usr/local/lib/python3.10/dist-packages/IPython/core/ultratb.py\", line 248, in wrapped\n","    return f(*args, **kwargs)\n","  File \"/usr/local/lib/python3.10/dist-packages/IPython/core/ultratb.py\", line 281, in _fixed_getinnerframes\n","    records = fix_frame_records_filenames(inspect.getinnerframes(etb, context))\n","  File \"/usr/lib/python3.10/inspect.py\", line 1662, in getinnerframes\n","    frameinfo = (tb.tb_frame,) + getframeinfo(tb, context)\n","  File \"/usr/lib/python3.10/inspect.py\", line 1620, in getframeinfo\n","    filename = getsourcefile(frame) or getfile(frame)\n","  File \"/usr/lib/python3.10/inspect.py\", line 829, in getsourcefile\n","    module = getmodule(object, filename)\n","  File \"/usr/lib/python3.10/inspect.py\", line 861, in getmodule\n","    file = getabsfile(object, _filename)\n","  File \"/usr/lib/python3.10/inspect.py\", line 845, in getabsfile\n","    return os.path.normcase(os.path.abspath(_filename))\n","  File \"/usr/lib/python3.10/posixpath.py\", line 384, in abspath\n","    cwd = os.getcwd()\n","OSError: [Errno 107] Transport endpoint is not connected\n","Traceback (most recent call last):\n","  File \"/usr/local/lib/python3.10/dist-packages/IPython/core/interactiveshell.py\", line 3553, in run_code\n","    exec(code_obj, self.user_global_ns, self.user_ns)\n","  File \"\u003cipython-input-16-72b12b7ac5f1\u003e\", line 3, in \u003ccell line: 3\u003e\n","    display = utils.notebook_init()  # checks\n","  File \"/gdrive/MyDrive/PHODO/Segmentation Model/Yolo_custom/yolov5/utils/__init__.py\", line 60, in notebook_init\n","    check_font()\n","  File \"/gdrive/MyDrive/PHODO/Segmentation Model/Yolo_custom/yolov5/utils/general.py\", line 500, in check_font\n","    if not font.exists() and not file.exists():\n","  File \"/usr/lib/python3.10/pathlib.py\", line 1290, in exists\n","    self.stat()\n","  File \"/usr/lib/python3.10/pathlib.py\", line 1097, in stat\n","    return self._accessor.stat(self, follow_symlinks=follow_symlinks)\n","OSError: [Errno 107] Transport endpoint is not connected: 'Arial.ttf'\n","\n","During handling of the above exception, another exception occurred:\n","\n","Traceback (most recent call last):\n","  File \"/usr/local/lib/python3.10/dist-packages/IPython/core/interactiveshell.py\", line 2099, in showtraceback\n","    stb = value._render_traceback_()\n","AttributeError: 'OSError' object has no attribute '_render_traceback_'\n","\n","During handling of the above exception, another exception occurred:\n","\n","Traceback (most recent call last):\n","  File \"/usr/local/lib/python3.10/dist-packages/IPython/core/interactiveshell.py\", line 3473, in run_ast_nodes\n","    if (await self.run_code(code, result,  async_=asy)):\n","  File \"/usr/local/lib/python3.10/dist-packages/IPython/core/interactiveshell.py\", line 3575, in run_code\n","    self.showtraceback(running_compiled_code=True)\n","  File \"/usr/local/lib/python3.10/dist-packages/IPython/core/interactiveshell.py\", line 2101, in showtraceback\n","    stb = self.InteractiveTB.structured_traceback(etype,\n","  File \"/usr/local/lib/python3.10/dist-packages/IPython/core/ultratb.py\", line 1367, in structured_traceback\n","    return FormattedTB.structured_traceback(\n","  File \"/usr/local/lib/python3.10/dist-packages/IPython/core/ultratb.py\", line 1267, in structured_traceback\n","    return VerboseTB.structured_traceback(\n","  File \"/usr/local/lib/python3.10/dist-packages/IPython/core/ultratb.py\", line 1124, in structured_traceback\n","    formatted_exception = self.format_exception_as_a_whole(etype, evalue, etb, number_of_lines_of_context,\n","  File \"/usr/local/lib/python3.10/dist-packages/IPython/core/ultratb.py\", line 1082, in format_exception_as_a_whole\n","    last_unique, recursion_repeat = find_recursion(orig_etype, evalue, records)\n","  File \"/usr/local/lib/python3.10/dist-packages/IPython/core/ultratb.py\", line 382, in find_recursion\n","    return len(records), 0\n","TypeError: object of type 'NoneType' has no len()\n","\n","During handling of the above exception, another exception occurred:\n","\n","Traceback (most recent call last):\n","  File \"/usr/local/lib/python3.10/dist-packages/IPython/core/interactiveshell.py\", line 2099, in showtraceback\n","    stb = value._render_traceback_()\n","AttributeError: 'TypeError' object has no attribute '_render_traceback_'\n","\n","During handling of the above exception, another exception occurred:\n","\n","Traceback (most recent call last):\n","  File \"/usr/local/lib/python3.10/dist-packages/IPython/core/ultratb.py\", line 1101, in get_records\n","    return _fixed_getinnerframes(etb, number_of_lines_of_context, tb_offset)\n","  File \"/usr/local/lib/python3.10/dist-packages/IPython/core/ultratb.py\", line 248, in wrapped\n","    return f(*args, **kwargs)\n","  File \"/usr/local/lib/python3.10/dist-packages/IPython/core/ultratb.py\", line 281, in _fixed_getinnerframes\n","    records = fix_frame_records_filenames(inspect.getinnerframes(etb, context))\n","  File \"/usr/lib/python3.10/inspect.py\", line 1662, in getinnerframes\n","    frameinfo = (tb.tb_frame,) + getframeinfo(tb, context)\n","  File \"/usr/lib/python3.10/inspect.py\", line 1620, in getframeinfo\n","    filename = getsourcefile(frame) or getfile(frame)\n","  File \"/usr/lib/python3.10/inspect.py\", line 829, in getsourcefile\n","    module = getmodule(object, filename)\n","  File \"/usr/lib/python3.10/inspect.py\", line 861, in getmodule\n","    file = getabsfile(object, _filename)\n","  File \"/usr/lib/python3.10/inspect.py\", line 845, in getabsfile\n","    return os.path.normcase(os.path.abspath(_filename))\n","  File \"/usr/lib/python3.10/posixpath.py\", line 384, in abspath\n","    cwd = os.getcwd()\n","OSError: [Errno 107] Transport endpoint is not connected\n","Traceback (most recent call last):\n","  File \"/usr/local/lib/python3.10/dist-packages/IPython/core/interactiveshell.py\", line 3553, in run_code\n","    exec(code_obj, self.user_global_ns, self.user_ns)\n","  File \"\u003cipython-input-16-72b12b7ac5f1\u003e\", line 3, in \u003ccell line: 3\u003e\n","    display = utils.notebook_init()  # checks\n","  File \"/gdrive/MyDrive/PHODO/Segmentation Model/Yolo_custom/yolov5/utils/__init__.py\", line 60, in notebook_init\n","    check_font()\n","  File \"/gdrive/MyDrive/PHODO/Segmentation Model/Yolo_custom/yolov5/utils/general.py\", line 500, in check_font\n","    if not font.exists() and not file.exists():\n","  File \"/usr/lib/python3.10/pathlib.py\", line 1290, in exists\n","    self.stat()\n","  File \"/usr/lib/python3.10/pathlib.py\", line 1097, in stat\n","    return self._accessor.stat(self, follow_symlinks=follow_symlinks)\n","OSError: [Errno 107] Transport endpoint is not connected: 'Arial.ttf'\n","\n","During handling of the above exception, another exception occurred:\n","\n","Traceback (most recent call last):\n","  File \"/usr/local/lib/python3.10/dist-packages/IPython/core/interactiveshell.py\", line 2099, in showtraceback\n","    stb = value._render_traceback_()\n","AttributeError: 'OSError' object has no attribute '_render_traceback_'\n","\n","During handling of the above exception, another exception occurred:\n","\n","Traceback (most recent call last):\n","  File \"/usr/local/lib/python3.10/dist-packages/IPython/core/interactiveshell.py\", line 3473, in run_ast_nodes\n","    if (await self.run_code(code, result,  async_=asy)):\n","  File \"/usr/local/lib/python3.10/dist-packages/IPython/core/interactiveshell.py\", line 3575, in run_code\n","    self.showtraceback(running_compiled_code=True)\n","  File \"/usr/local/lib/python3.10/dist-packages/IPython/core/interactiveshell.py\", line 2101, in showtraceback\n","    stb = self.InteractiveTB.structured_traceback(etype,\n","  File \"/usr/local/lib/python3.10/dist-packages/IPython/core/ultratb.py\", line 1367, in structured_traceback\n","    return FormattedTB.structured_traceback(\n","  File \"/usr/local/lib/python3.10/dist-packages/IPython/core/ultratb.py\", line 1267, in structured_traceback\n","    return VerboseTB.structured_traceback(\n","  File \"/usr/local/lib/python3.10/dist-packages/IPython/core/ultratb.py\", line 1124, in structured_traceback\n","    formatted_exception = self.format_exception_as_a_whole(etype, evalue, etb, number_of_lines_of_context,\n","  File \"/usr/local/lib/python3.10/dist-packages/IPython/core/ultratb.py\", line 1082, in format_exception_as_a_whole\n","    last_unique, recursion_repeat = find_recursion(orig_etype, evalue, records)\n","  File \"/usr/local/lib/python3.10/dist-packages/IPython/core/ultratb.py\", line 382, in find_recursion\n","    return len(records), 0\n","TypeError: object of type 'NoneType' has no len()\n","\n","During handling of the above exception, another exception occurred:\n","\n","Traceback (most recent call last):\n","  File \"/usr/local/lib/python3.10/dist-packages/IPython/core/interactiveshell.py\", line 2099, in showtraceback\n","    stb = value._render_traceback_()\n","AttributeError: 'TypeError' object has no attribute '_render_traceback_'\n","\n","During handling of the above exception, another exception occurred:\n","\n","Traceback (most recent call last):\n","  File \"/usr/local/lib/python3.10/dist-packages/IPython/core/interactiveshell.py\", line 3030, in _run_cell\n","    return runner(coro)\n","  File \"/usr/local/lib/python3.10/dist-packages/IPython/core/async_helpers.py\", line 78, in _pseudo_sync_runner\n","    coro.send(None)\n","  File \"/usr/local/lib/python3.10/dist-packages/IPython/core/interactiveshell.py\", line 3257, in run_cell_async\n","    has_raised = await self.run_ast_nodes(code_ast.body, cell_name,\n","  File \"/usr/local/lib/python3.10/dist-packages/IPython/core/interactiveshell.py\", line 3492, in run_ast_nodes\n","    self.showtraceback()\n","  File \"/usr/local/lib/python3.10/dist-packages/IPython/core/interactiveshell.py\", line 2101, in showtraceback\n","    stb = self.InteractiveTB.structured_traceback(etype,\n","  File \"/usr/local/lib/python3.10/dist-packages/IPython/core/ultratb.py\", line 1367, in structured_traceback\n","    return FormattedTB.structured_traceback(\n","  File \"/usr/local/lib/python3.10/dist-packages/IPython/core/ultratb.py\", line 1267, in structured_traceback\n","    return VerboseTB.structured_traceback(\n","  File \"/usr/local/lib/python3.10/dist-packages/IPython/core/ultratb.py\", line 1142, in structured_traceback\n","    formatted_exceptions += self.format_exception_as_a_whole(etype, evalue, etb, lines_of_context,\n","  File \"/usr/local/lib/python3.10/dist-packages/IPython/core/ultratb.py\", line 1082, in format_exception_as_a_whole\n","    last_unique, recursion_repeat = find_recursion(orig_etype, evalue, records)\n","  File \"/usr/local/lib/python3.10/dist-packages/IPython/core/ultratb.py\", line 382, in find_recursion\n","    return len(records), 0\n","TypeError: object of type 'NoneType' has no len()\n","\n","During handling of the above exception, another exception occurred:\n","\n","Traceback (most recent call last):\n","  File \"/usr/local/lib/python3.10/dist-packages/IPython/core/interactiveshell.py\", line 2099, in showtraceback\n","    stb = value._render_traceback_()\n","AttributeError: 'TypeError' object has no attribute '_render_traceback_'\n","\n","During handling of the above exception, another exception occurred:\n","\n","Traceback (most recent call last):\n","  File \"/usr/local/lib/python3.10/dist-packages/IPython/core/ultratb.py\", line 1101, in get_records\n","    return _fixed_getinnerframes(etb, number_of_lines_of_context, tb_offset)\n","  File \"/usr/local/lib/python3.10/dist-packages/IPython/core/ultratb.py\", line 248, in wrapped\n","    return f(*args, **kwargs)\n","  File \"/usr/local/lib/python3.10/dist-packages/IPython/core/ultratb.py\", line 281, in _fixed_getinnerframes\n","    records = fix_frame_records_filenames(inspect.getinnerframes(etb, context))\n","  File \"/usr/lib/python3.10/inspect.py\", line 1662, in getinnerframes\n","    frameinfo = (tb.tb_frame,) + getframeinfo(tb, context)\n","  File \"/usr/lib/python3.10/inspect.py\", line 1620, in getframeinfo\n","    filename = getsourcefile(frame) or getfile(frame)\n","  File \"/usr/lib/python3.10/inspect.py\", line 829, in getsourcefile\n","    module = getmodule(object, filename)\n","  File \"/usr/lib/python3.10/inspect.py\", line 861, in getmodule\n","    file = getabsfile(object, _filename)\n","  File \"/usr/lib/python3.10/inspect.py\", line 845, in getabsfile\n","    return os.path.normcase(os.path.abspath(_filename))\n","  File \"/usr/lib/python3.10/posixpath.py\", line 384, in abspath\n","    cwd = os.getcwd()\n","OSError: [Errno 107] Transport endpoint is not connected\n"]}],"source":["import torch\n","import utils\n","display = utils.notebook_init()  # checks"]},{"cell_type":"code","execution_count":5,"metadata":{"executionInfo":{"elapsed":17,"status":"ok","timestamp":1683530254702,"user":{"displayName":"갱단","userId":"00887275859011159220"},"user_tz":-540},"id":"eeS8wjfEZSEY"},"outputs":[],"source":["from utils.downloads import attempt_download\n","\n","p5 = ['n', 's', 'm', 'l', 'x']  # P5 models\n","cls = [f'{x}-seg' for x in p5]  # segmentation models\n","\n","for x in cls:\n","    attempt_download(f'/gdrive/My Drive/PHODO/Segmentation Model/Yolo_custom/yolov5/weights/yolov5{x}.pt')"]},{"cell_type":"code","execution_count":9,"metadata":{"colab":{"base_uri":"https://localhost:8080/"},"executionInfo":{"elapsed":61741,"status":"ok","timestamp":1683531091498,"user":{"displayName":"갱단","userId":"00887275859011159220"},"user_tz":-540},"id":"P1Ib1EIlZYEx","outputId":"3f3c60b9-a3cd-485f-99c8-ee6a5d22132f"},"outputs":[{"name":"stdout","output_type":"stream","text":["/gdrive/My Drive/PHODO/Segmentation Model/Yolo_custom/yolov5\n","\u001b[34m\u001b[1msegment/predict: \u001b[0mweights=['weights/yolov5x-seg.pt'], source=data/images/custom_test/colo.jpg, data=data/coco128.yaml, imgsz=[640, 640], conf_thres=0.25, iou_thres=0.45, max_det=1000, device=, view_img=False, save_txt=False, save_conf=False, save_crop=False, nosave=False, classes=None, agnostic_nms=False, augment=False, visualize=False, update=False, project=runs/predict-seg, name=exp, exist_ok=False, line_thickness=3, hide_labels=False, hide_conf=False, half=False, dnn=False, vid_stride=1, retina_masks=False\n","YOLOv5 🚀 2023-4-8 Python-3.10.11 torch-2.0.0+cu118 CUDA:0 (Tesla T4, 15102MiB)\n","\n","Fusing layers... \n","YOLOv5x-seg summary: 455 layers, 88774445 parameters, 0 gradients\n","NMS 시작!!!!\n","prediction.shape : torch.Size([1, 18900, 117])\n","13 persons, \n","1 airplane, \n","1 backpack, \n","1 handbag, \n","labels : tensor([ 0.,  0.,  0.,  0.,  0.,  0.,  0.,  0., 26.,  0.,  0., 24.,  0.,  0.,  0.,  4.], device='cuda:0')\n","person_color : (tensor([[[[1., 1., 1.]]],\n","\n","\n","        [[[1., 1., 1.]]],\n","\n","\n","        [[[1., 1., 1.]]],\n","\n","\n","        [[[1., 1., 1.]]],\n","\n","\n","        [[[1., 1., 1.]]],\n","\n","\n","        [[[1., 1., 1.]]],\n","\n","\n","        [[[1., 1., 1.]]],\n","\n","\n","        [[[1., 1., 1.]]],\n","\n","\n","        [[[1., 1., 1.]]],\n","\n","\n","        [[[1., 1., 1.]]],\n","\n","\n","        [[[1., 1., 1.]]],\n","\n","\n","        [[[1., 1., 1.]]],\n","\n","\n","        [[[1., 1., 1.]]]], device='cuda:0'), torch.Size([13, 1, 1, 3]))\n","im_mask : (640, 480, 3)\n","person_masks : torch.Size([13, 640, 480, 1])\n"]}],"source":["%cd /gdrive/My Drive/PHODO/Segmentation Model/Yolo_custom/yolov5\n","!python segment/predict.py --weights weights/yolov5x-seg.pt --source data/images/custom_test/colo.jpg #--name '' #옵션주면 해당 경로에 결과 저장"]},{"cell_type":"code","execution_count":null,"metadata":{"id":"mt3w2o1eW_q0"},"outputs":[],"source":[]},{"cell_type":"code","execution_count":null,"metadata":{"id":"8qmHrx7q3IaB"},"outputs":[],"source":[]},{"cell_type":"code","execution_count":null,"metadata":{"id":"6CKRXAPbaNCs"},"outputs":[],"source":["display.Image(filename=f\"/gdrive/My Drive/PHODO/Segmentation Model/Yolo/yolov5/runs/predict-seg/test-inference5/firenze.jpg\", width=600)"]},{"cell_type":"code","execution_count":null,"metadata":{"id":"LaVE2e6obgxV"},"outputs":[],"source":[]}],"metadata":{"accelerator":"GPU","colab":{"authorship_tag":"ABX9TyOchZqJkxff/vLYJeBsvgHP","mount_file_id":"1hsvqpw5q79snaW7X384ltEO9piUB38pl","name":"","version":""},"gpuClass":"standard","kernelspec":{"display_name":"Python 3","name":"python3"},"language_info":{"name":"python"}},"nbformat":4,"nbformat_minor":0}